Workbook

Sheet Scope
A1: The Heat to Come | B1: Payoff reference and selected checks
A2: Release | B2: Application 2.5.0 / model V2-2.3.0 / dossier 2026-09-26
A3: Purpose | B3: Technical teaching reference. Synthetic educational values, not real-world forecasts.
A4: Scope | B4: Parameters plus selected budget, coordination, risk, acceptability and payoff calculations.
A5: No full engine parity | B5: No complete turn simulation, random draw, lifecycle replay, damage or final-score replication.
A6: Coordination boundary | B6: Spanning-link counts are engine-derived fixture inputs. This workbook does not solve the graph.
A7: Input meaning | B7: Amber cells in Budget, Coordination and Risk are editable teaching inputs.
A8: Frozen source values | B8: Source tables reproduce the qualified model. Editing them makes a local experiment.
A9: Versions | B9: Application 2.5.0 is not model 2.5.0. Historical V1 budgets/rules are not current.
A10: Language | B10: English guide and headings. Original internal Italian pair/mix notes are excluded from this public extract.
A11: Data companion | B11: ../technical/technical-data-extract.json contains full event branches, lifecycle metadata and model parameters.
A12: Interpretation | B12: Risk, resilience and acceptability are synthetic points; budget is resource units, not currency.
... A21: Rules fingerprint | B21: rules-v2.3.0-coordination-pair-normalisation-2026-09-26.1

Sheet Budget
A1: Scenario | B1: Turn | C1: Release | D1: Carry in | E1: Pending delta | F1: Available | G1: Spending | H1: Event delta | I1: Carry out
A2: PC | B2: 1 | C2: =Scenarios!F2 -> 44 | D2: =0 -> 0 | E2: 0 | F2: =C2+D2+E2 -> 44 | G2: 0 | H2: 0 | I2: =F2-G2+H2 -> 44
A3: PC | B3: 2 | C3: =Scenarios!G2 -> 33 | D3: =I2 -> 44 | E3: 0 | F3: =C3+D3+E3 -> 77 | G3: 0 | H3: 0 | I3: =F3-G3+H3 -> 77
A4: PC | B4: 3 | C4: =Scenarios!H2 -> 23 | D4: =I3 -> 77 | E4: 0 | F4: =C4+D4+E4 -> 100 | G4: 0 | H4: 0 | I4: =F4-G4+H4 -> 100
A5: FF | B5: 1 | C5: =Scenarios!F3 -> 32 | D5: =0 -> 0 | E5: 0 | F5: =C5+D5+E5 -> 32 | G5: 0 | H5: 0 | I5: =F5-G5+H5 -> 32
A6: FF | B6: 2 | C6: =Scenarios!G3 -> 23 | D6: =I5 -> 32 | E6: 0 | F6: =C6+D6+E6 -> 55 | G6: 0 | H6: 0 | I6: =F6-G6+H6 -> 55
A7: FF | B7: 3 | C7: =Scenarios!H3 -> 15 | D7: =I6 -> 55 | E7: 0 | F7: =C7+D7+E7 -> 70 | G7: 0 | H7: 0 | I7: =F7-G7+H7 -> 70
A8: CZ | B8: 1 | C8: =Scenarios!F4 -> 40 | D8: =0 -> 0 | E8: 0 | F8: =C8+D8+E8 -> 40 | G8: 0 | H8: 0 | I8: =F8-G8+H8 -> 40
A9: CZ | B9: 2 | C9: =Scenarios!G4 -> 35 | D9: =I8 -> 40 | E9: 0 | F9: =C9+D9+E9 -> 75 | G9: 0 | H9: 0 | I9: =F9-G9+H9 -> 75
A10: CZ | B10: 3 | C10: =Scenarios!H4 -> 25 | D10: =I9 -> 75 | E10: 0 | F10: =C10+D10+E10 -> 100 | G10: 0 | H10: 0 | I10: =F10-G10+H10 -> 100
A11: SR | B11: 1 | C11: =Scenarios!F5 -> 33 | D11: =0 -> 0 | E11: 0 | F11: =C11+D11+E11 -> 33 | G11: 0 | H11: 0 | I11: =F11-G11+H11 -> 33
A12: SR | B12: 2 | C12: =Scenarios!G5 -> 22 | D12: =I11 -> 33 | E12: 0 | F12: =C12+D12+E12 -> 55 | G12: 0 | H12: 0 | I12: =F12-G12+H12 -> 55
A13: SR | B13: 3 | C13: =Scenarios!H5 -> 15 | D13: =I12 -> 55 | E13: 0 | F13: =C13+D13+E13 -> 70 | G13: 0 | H13: 0 | I13: =F13-G13+H13 -> 70

Sheet Coordination
A1: Fixture | B1: Starts | C1: Upgrades | D1: Repairs | E1: Categories | F1: Forest links | G1: Built bonus | H1: Action load | I1: H load | J1: Credit | K1: Net load | L1: Capacity | M1: Excess | N1: Eta
A2: CO-1 | B2: 0 | C2: 0 | D2: 0 | E2: 0 | F2: 0 | G2: 0 | H2: =ROUND(B2*Parameters!$B$3+C2*Parameters!$B$4+D2*Parameters!$B$5,6) -> 0 | I2: =INDEX(Parameters!$B$6:$B$12,E2+1) -> 0 | J2: =MIN(I2,F2*Parameters!$B$13) -> 0 | K2: =ROUND(MAX(0,H2+I2-J2),6) -> 0 | L2: =Parameters!$B$14+G2 -> 4 | M2: =ROUND(MAX(0,K2-L2),6) -> 0 | N2: =ROUND(1/(1+Parameters!$B$15*M2^Parameters!$B$16),6) -> 1
A3: CO-2 | B3: 4 | C3: 0 | D3: 0 | E3: 1 | F3: 0 | G3: 0 | H3: =ROUND(B3*Parameters!$B$3+C3*Parameters!$B$4+D3*Parameters!$B$5,6) -> 1.6 | I3: =INDEX(Parameters!$B$6:$B$12,E3+1) -> 0 | J3: =MIN(I3,F3*Parameters!$B$13) -> 0 | K3: =ROUND(MAX(0,H3+I3-J3),6) -> 1.6 | L3: =Parameters!$B$14+G3 -> 4 | M3: =ROUND(MAX(0,K3-L3),6) -> 0 | N3: =ROUND(1/(1+Parameters!$B$15*M3^Parameters!$B$16),6) -> 1
A4: CO-3 | B4: 4 | C4: 0 | D4: 0 | E4: 4 | F4: 3 | G4: 0 | H4: =ROUND(B4*Parameters!$B$3+C4*Parameters!$B$4+D4*Parameters!$B$5,6) -> 1.6 | I4: =INDEX(Parameters!$B$6:$B$12,E4+1) -> 3 | J4: =MIN(I4,F4*Parameters!$B$13) -> 1.5 | K4: =ROUND(MAX(0,H4+I4-J4),6) -> 3.1 | L4: =Parameters!$B$14+G4 -> 4 | M4: =ROUND(MAX(0,K4-L4),6) -> 0 | N4: =ROUND(1/(1+Parameters!$B$15*M4^Parameters!$B$16),6) -> 1
A5: CO-4 | B5: 6 | C5: 0 | D5: 0 | E5: 6 | F5: 5 | G5: 0 | H5: =ROUND(B5*Parameters!$B$3+C5*Parameters!$B$4+D5*Parameters!$B$5,6) -> 2.4 | I5: =INDEX(Parameters!$B$6:$B$12,E5+1) -> 10 | J5: =MIN(I5,F5*Parameters!$B$13) -> 2.5 | K5: =ROUND(MAX(0,H5+I5-J5),6) -> 9.9 | L5: =Parameters!$B$14+G5 -> 4 | M5: =ROUND(MAX(0,K5-L5),6) -> 5.9 | N5: =ROUND(1/(1+Parameters!$B$15*M5^Parameters!$B$16),6) -> 0.279362

Sheet Risk
A1: Case | B1: Current risk | C1: Penalty | D1: Reduction | E1: Floor | F1: k | G1: New risk
A2: PC:0 | B2: 85 | C2: 0 | D2: 0 | E2: =Scenarios!I2 -> 10 | F2: =Scenarios!J2 -> 22 | G2: =IF(COUNT(B2:F2)<5,"Missing input",IF(F2<=0,"Invalid k",ROUND(MIN(140,MAX(E2,E2+(MAX(E2,B2+MAX(0,C2))-E2)*EXP(-MAX(0,D2)/F2))),3))) -> 85
A3: PC:10 | B3: 85 | C3: 0 | D3: 10 | E3: =Scenarios!I2 -> 10 | F3: =Scenarios!J2 -> 22 | G3: =IF(COUNT(B3:F3)<5,"Missing input",IF(F3<=0,"Invalid k",ROUND(MIN(140,MAX(E3,E3+(MAX(E3,B3+MAX(0,C3))-E3)*EXP(-MAX(0,D3)/F3))),3))) -> 57.605
A4: PC:10000 | B4: 85 | C4: 0 | D4: 10000 | E4: =Scenarios!I2 -> 10 | F4: =Scenarios!J2 -> 22 | G4: =IF(COUNT(B4:F4)<5,"Missing input",IF(F4<=0,"Invalid k",ROUND(MIN(140,MAX(E4,E4+(MAX(E4,B4+MAX(0,C4))-E4)*EXP(-MAX(0,D4)/F4))),3))) -> 10
A5: FF:0 | B5: 90 | C5: 0 | D5: 0 | E5: =Scenarios!I3 -> 15 | F5: =Scenarios!J3 -> 27 | G5: =IF(COUNT(B5:F5)<5,"Missing input",IF(F5<=0,"Invalid k",ROUND(MIN(140,MAX(E5,E5+(MAX(E5,B5+MAX(0,C5))-E5)*EXP(-MAX(0,D5)/F5))),3))) -> 90
A6: FF:10 | B6: 90 | C6: 0 | D6: 10 | E6: =Scenarios!I3 -> 15 | F6: =Scenarios!J3 -> 27 | G6: =IF(COUNT(B6:F6)<5,"Missing input",IF(F6<=0,"Invalid k",ROUND(MIN(140,MAX(E6,E6+(MAX(E6,B6+MAX(0,C6))-E6)*EXP(-MAX(0,D6)/F6))),3))) -> 66.786
A7: FF:10000 | B7: 90 | C7: 0 | D7: 10000 | E7: =Scenarios!I3 -> 15 | F7: =Scenarios!J3 -> 27 | G7: =IF(COUNT(B7:F7)<5,"Missing input",IF(F7<=0,"Invalid k",ROUND(MIN(140,MAX(E7,E7+(MAX(E7,B7+MAX(0,C7))-E7)*EXP(-MAX(0,D7)/F7))),3))) -> 15
A8: CZ:0 | B8: 35 | C8: 0 | D8: 0 | E8: =Scenarios!I4 -> 5 | F8: =Scenarios!J4 -> 8 | G8: =IF(COUNT(B8:F8)<5,"Missing input",IF(F8<=0,"Invalid k",ROUND(MIN(140,MAX(E8,E8+(MAX(E8,B8+MAX(0,C8))-E8)*EXP(-MAX(0,D8)/F8))),3))) -> 35
A9: CZ:10 | B9: 35 | C9: 0 | D9: 10 | E9: =Scenarios!I4 -> 5 | F9: =Scenarios!J4 -> 8 | G9: =IF(COUNT(B9:F9)<5,"Missing input",IF(F9<=0,"Invalid k",ROUND(MIN(140,MAX(E9,E9+(MAX(E9,B9+MAX(0,C9))-E9)*EXP(-MAX(0,D9)/F9))),3))) -> 13.595
A10: CZ:10000 | B10: 35 | C10: 0 | D10: 10000 | E10: =Scenarios!I4 -> 5 | F10: =Scenarios!J4 -> 8 | G10: =IF(COUNT(B10:F10)<5,"Missing input",IF(F10<=0,"Invalid k",ROUND(MIN(140,MAX(E10,E10+(MAX(E10,B10+MAX(0,C10))-E10)*EXP(-MAX(0,D10)/F10))),3))) -> 5
A11: SR:0 | B11: 40 | C11: 0 | D11: 0 | E11: =Scenarios!I5 -> 8 | F11: =Scenarios!J5 -> 11 | G11: =IF(COUNT(B11:F11)<5,"Missing input",IF(F11<=0,"Invalid k",ROUND(MIN(140,MAX(E11,E11+(MAX(E11,B11+MAX(0,C11))-E11)*EXP(-MAX(0,D11)/F11))),3))) -> 40
A12: SR:10 | B12: 40 | C12: 0 | D12: 10 | E12: =Scenarios!I5 -> 8 | F12: =Scenarios!J5 -> 11 | G12: =IF(COUNT(B12:F12)<5,"Missing input",IF(F12<=0,"Invalid k",ROUND(MIN(140,MAX(E12,E12+(MAX(E12,B12+MAX(0,C12))-E12)*EXP(-MAX(0,D12)/F12))),3))) -> 20.892
A13: SR:10000 | B13: 40 | C13: 0 | D13: 10000 | E13: =Scenarios!I5 -> 8 | F13: =Scenarios!J5 -> 11 | G13: =IF(COUNT(B13:F13)<5,"Missing input",IF(F13<=0,"Invalid k",ROUND(MIN(140,MAX(E13,E13+(MAX(E13,B13+MAX(0,C13))-E13)*EXP(-MAX(0,D13)/F13))),3))) -> 8

Sheet Acceptability
A1: Effective-level input | B1: Cost units | C1: Acceptability | D1: Weighted contribution
A2: INF01 | B2: 11 | C2: 86 | D2: =B2*C2 -> 946
A3: INF02 | B3: 9 | C3: 82 | D3: =B3*C3 -> 738
A4: INF03 | B4: 7 | C4: 84 | D4: =B4*C4 -> 588
A6: Total cost | B6: =SUM(B2:B4) -> 27
A7: Weighted mean | B7: =IF(B6=0,AVERAGE(C2:C4),SUM(D2:D4)/B6) -> 84.148148
A8: Package minimum | B8: =MIN(C2:C4) -> 82
A9: Package acceptability | B9: =ROUND(B7*Parameters!$B$34+B8*Parameters!$B$35,3) -> 83.504

Sheet Payoff checks
A1: Example | B1: Input 1 | C1: Input 2 | D1: Input 3 | E1: Result | F1: Meaning
A2: Pair L1/L1 | B2: 1 | C2: 1 | D2: 0 | E2: =B2*C2/4 -> 0.25 | F2: Positive pair intensity
A3: Pair L1/L2 | B3: 1 | C3: 2 | D3: 0 | E3: =B3*C3/4 -> 0.5 | F3: Positive pair intensity
A4: Pair L2/L2 | B4: 2 | C4: 2 | D4: 0 | E4: =B4*C4/4 -> 1 | F4: Positive pair intensity
A5: Negative L1/L1 | B5: 1 | C5: 1 | D5: 0 | E5: =MAX(0.5,B5*C5/4) -> 0.5 | F5: Negative pair minimum intensity
A6: Risk cap zero | B6: 0 | C6: 0 | D6: 0 | E6: =MIN(Parameters!$B$27,0.15*MAX(0,B6)) -> 0 | F6: Cap on positive risk sum
A7: Risk cap 100 | B7: 100 | C7: 0 | D7: 0 | E7: =MIN(Parameters!$B$27,0.15*MAX(0,B7)) -> 8 | F7: Cap on positive risk sum
A8: Resilience cap 100 | B8: 100 | C8: 0 | D8: 0 | E8: =MIN(Parameters!$B$28,0.2*MAX(0,B8)) -> 10 | F8: Cap on positive resilience sum
A9: Saturation rank 1 | B9: 1 | C9: 0 | D9: 0 | E9: =Parameters!$B$19 -> 1 | F9: Applied after metric-specific ranking
A10: Saturation rank 2 | B10: 2 | C10: 0 | D10: 0 | E10: =Parameters!$B$20 -> 1 | F10: Applied after metric-specific ranking
A11: Saturation rank 3 | B11: 3 | C11: 0 | D11: 0 | E11: =Parameters!$B$21 -> 0.75 | F11: Applied after metric-specific ranking
A12: Saturation rank 4 | B12: 4 | C12: 0 | D12: 0 | E12: =Parameters!$B$22 -> 0.5 | F12: Applied after metric-specific ranking
A13: Saturation rank 5 | B13: 5 | C13: 0 | D13: 0 | E13: =Parameters!$B$23 -> 0.25 | F13: Applied after metric-specific ranking
A14: Saturation rank 6 | B14: 6 | C14: 0 | D14: 0 | E14: =Parameters!$B$24 -> 0.1 | F14: Applied after metric-specific ranking
A15: Mix boundary | B15: 0.35 | C15: 0.29 | D15: 0 | E15: =IF(AND(B15>'Category mix'!C2,C15<'Category mix'!E2),1,0) -> 0 | F15: INF: strictly above 0.35 and below 0.30
A16: Mix above | B16: 0.350001 | C16: 0.29 | D16: 0 | E16: =IF(AND(B16>'Category mix'!C2,C16<'Category mix'!E2),1,0) -> 1 | F16: INF: both strict conditions true
A17: Mix complement boundary | B17: 0.36 | C17: 0.3 | D17: 0 | E17: =IF(AND(B17>'Category mix'!C2,C17<'Category mix'!E2),1,0) -> 0 | F17: INF: complement boundary does not trigger

Sheet Scenarios
A1: ID | B1: Scenario | C1: Risk base | D1: Resilience base | E1: Budget units | F1: T1 release | G1: T2 release | H1: T3 release | I1: Risk floor | J1: Risk k
A2: PC | B2: The Pressure Cooker | C2: 85 | D2: 55 | E2: 100 | F2: 44 | G2: 33 | H2: 23 | I2: 10 | J2: 22
A3: FF | B3: The Fragile Frontline | C3: 90 | D3: 30 | E3: 70 | F3: 32 | G3: 23 | H3: 15 | I3: 15 | J3: 27
A4: CZ | B4: The Comfort Zone | C4: 35 | D4: 75 | E4: 100 | F4: 40 | G4: 35 | H4: 25 | I4: 5 | J4: 8
A5: SR | B5: The Silent Risk | C5: 40 | D5: 35 | E5: 70 | F5: 33 | G5: 22 | H5: 15 | I5: 8 | J5: 11

Sheet Readiness
A1: Scenario | B1: Category | C1: Readiness factor
A2: PC | B2: Infrastructure | C2: 1.05
A3: PC | B3: Operations | C3: 1.54
A4: PC | B4: Preparedness | C4: 1.47
A5: PC | B5: Governance | C5: 1
A6: PC | B6: Behavioural | C6: 0.95
A7: PC | B7: Restrictive | C7: 0.95
A8: FF | B8: Infrastructure | C8: 0.85
A9: FF | B9: Operations | C9: 1.76
A10: FF | B10: Preparedness | C10: 1.84
A11: FF | B11: Governance | C11: 1.05
A12: FF | B12: Behavioural | C12: 1.76
A13: FF | B13: Restrictive | C13: 1
... A25: SR | B25: Restrictive | C25: 0.95

Sheet Score weights
A1: Scenario | B1: Risk | C1: Resilience | D1: Coherence + continuity | E1: Acceptability | F1: Efficiency
A2: PC | B2: 40 | C2: 30 | D2: 15 | E2: 10 | F2: 5
A3: FF | B3: 30 | C3: 35 | D3: 20 | E3: 10 | F3: 5
A4: CZ | B4: 15 | C4: 25 | D4: 25 | E4: 15 | F4: 20
A5: SR | B5: 15 | C5: 40 | D5: 25 | E5: 10 | F5: 10

Sheet Payoffs
A1: Runtime ID | B1: Intervention | C1: Category | D1: Level | E1: Cost units | F1: Risk reduction | G1: Resilience gain | H1: Acceptability
A2: INF01 | B2: Urban greening and vegetation-based cooling | C2: Infrastructure | D2: 0 | E2: 0 | F2: 0 | G2: 0 | H2: 0
A3: INF01 | B3: Urban greening and vegetation-based cooling | C3: Infrastructure | D3: 1 | E3: 11 | F3: 5 | G3: 6 | H3: 86
A4: INF01 | B4: Urban greening and vegetation-based cooling | C4: Infrastructure | D4: 2 | E4: 23 | F4: 10 | G4: 11 | H4: 90
A5: INF02 | B5: Cool surfaces and passive cooling materials | C5: Infrastructure | D5: 0 | E5: 0 | F5: 0 | G5: 0 | H5: 0
A6: INF02 | B6: Cool surfaces and passive cooling materials | C6: Infrastructure | D6: 1 | E6: 9 | F6: 6 | G6: 6 | H6: 82
A7: INF02 | B7: Cool surfaces and passive cooling materials | C7: Infrastructure | D7: 2 | E7: 20 | F7: 13 | G7: 12 | H7: 78
A8: INF03 | B8: Shaded areas and cooling shelters | C8: Infrastructure | D8: 0 | E8: 0 | F8: 0 | G8: 0 | H8: 0
A9: INF03 | B9: Shaded areas and cooling shelters | C9: Infrastructure | D9: 1 | E9: 7 | F9: 7 | G9: 7 | H9: 84
A10: INF03 | B10: Shaded areas and cooling shelters | C10: Infrastructure | D10: 2 | E10: 15 | F10: 14 | G10: 13 | H10: 88
A11: INF04 | B11: Thermal retrofit of critical campus buildings | C11: Infrastructure | D11: 0 | E11: 0 | F11: 0 | G11: 0 | H11: 0
A12: INF04 | B12: Thermal retrofit of critical campus buildings | C12: Infrastructure | D12: 1 | E12: 13 | F12: 6 | G12: 7 | H12: 74
A13: INF04 | B13: Thermal retrofit of critical campus buildings | C13: Infrastructure | D13: 2 | E13: 29 | F13: 12 | G13: 15 | H13: 76
... A109: RES06 | B109: Recurrent general closures as an ordinary strategy | C109: Restrictive | D109: 2 | E109: 15 | F109: 18 | G109: -2 | H109: 25

Sheet Lifecycle
A1: Runtime ID | B1: Class (legacy) | C1: Delivery class | D1: L1 delay | E1: L2 delay | F1: Repair cost | G1: L1 maturity | H1: Direct L2 maturity | I1: Upgrade maturity | J1: Capability tags
A2: INF01 | B2: permanent | C2: infrastructure | D2: 1 | E2: 1 | F2: 0 | G2: 0, 1, 1 | H2: 0, 0.5, 1 | I2: 0, 1, 1 | J2: cooling, shelter
A3: INF02 | B3: permanent | C3: infrastructure | D3: 1 | E3: 1 | F3: 0 | G3: 0, 1, 1 | H3: 0, 0.5, 1 | I3: 0, 1, 1 | J3: cooling, shelter
A4: INF03 | B4: permanent | C4: infrastructure | D4: 1 | E4: 1 | F4: 0 | G4: 0, 1, 1 | H4: 0, 0.5, 1 | I4: 0, 1, 1 | J4: cooling, shelter
A5: INF04 | B5: permanent | C5: infrastructure | D5: 1 | E5: 1 | F5: 0 | G5: 0, 1, 1 | H5: 0, 0.5, 1 | I5: 0, 1, 1 | J5: cooling, shelter
A6: INF05 | B6: permanent | C6: infrastructure | D6: 1 | E6: 1 | F6: 0 | G6: 0, 1, 1 | H6: 0, 0.5, 1 | I6: 0, 1, 1 | J6: cooling, shelter
A7: INF06 | B7: permanent | C7: infrastructure | D7: 1 | E7: 1 | F7: 0 | G7: 0, 1, 1 | H7: 0, 0.5, 1 | I7: 0, 1, 1 | J7: cooling, shelter
A8: OPS01 | B8: persistent | C8: programme | D8: 0 | E8: 0 | F8: 1 | G8: 1, 1, 1 | H8: 0.5, 1, 1 | I8: 0, 1, 1 | J8: continuity, monitoring
A9: OPS02 | B9: persistent | C9: programme | D9: 0 | E9: 0 | F9: 1 | G9: 1, 1, 1 | H9: 0.5, 1, 1 | I9: 0, 1, 1 | J9: continuity, monitoring
A10: OPS03 | B10: persistent | C10: programme | D10: 0 | E10: 0 | F10: 1 | G10: 1, 1, 1 | H10: 0.5, 1, 1 | I10: 0, 1, 1 | J10: continuity, monitoring
A11: OPS04 | B11: persistent | C11: programme | D11: 0 | E11: 0 | F11: 1 | G11: 1, 1, 1 | H11: 0.5, 1, 1 | I11: 0, 1, 1 | J11: continuity, monitoring
A12: OPS05 | B12: persistent | C12: programme | D12: 0 | E12: 0 | F12: 1 | G12: 1, 1, 1 | H12: 0.5, 1, 1 | I12: 0, 1, 1 | J12: continuity, monitoring
A13: OPS06 | B13: persistent | C13: programme | D13: 0 | E13: 0 | F13: 1 | G13: 1, 1, 1 | H13: 0.5, 1, 1 | I13: 0, 1, 1 | J13: continuity, monitoring
... A37: RES06 | B37: temporary | C37: immediate | D37: 0 | E37: 0 | F37: 1 | G37: 1, 1, 1 | H37: 1, 1, 1 | I37: 1, 1, 1 | J37: restriction, continuity

Sheet Interactions
A1: Pair key | B1: ID 1 | C1: ID 2 | D1: Risk payoff | E1: Resilience payoff
A2: INF01|INF02 | B2: INF01 | C2: INF02 | D2: 2 | E2: 0
A3: INF01|INF03 | B3: INF01 | C3: INF03 | D3: 3 | E3: 2
A4: INF01|INF05 | B4: INF01 | C4: INF05 | D4: 3 | E4: 2
A5: INF01|OPS02 | B5: INF01 | C5: OPS02 | D5: 2 | E5: 0
A6: INF01|OPS05 | B6: INF01 | C6: OPS05 | D6: 2 | E6: 0
A7: INF01|OPS06 | B7: INF01 | C7: OPS06 | D7: -1 | E7: 0
A8: INF01|PRE04 | B8: INF01 | C8: PRE04 | D8: 2 | E8: 0
A9: INF01|GOV01 | B9: INF01 | C9: GOV01 | D9: 0 | E9: 1
A10: INF01|GOV02 | B10: INF01 | C10: GOV02 | D10: 0 | E10: 1
A11: INF01|GOV03 | B11: INF01 | C11: GOV03 | D11: 2 | E11: 2
A12: INF01|GOV04 | B12: INF01 | C12: GOV04 | D12: 2 | E12: 2
A13: INF01|GOV05 | B13: INF01 | C13: GOV05 | D13: 0 | E13: 1
... A273: RES05|RES06 | B273: RES05 | C273: RES06 | D273: -2 | E273: -2

Sheet Category mix
A1: Rule ID | B1: Dominant category | C1: Share above | D1: Complement categories | E1: Share below | F1: Risk payoff | G1: Resilience payoff
A2: INF_CONC | B2: Infrastructure | C2: 0.35 | D2: Operations+Preparedness+Governance | E2: 0.3 | F2: -1 | G2: -4
A3: OPS_CONC | B3: Operations | C3: 0.35 | D3: Infrastructure+Preparedness+Governance | E3: 0.3 | F3: -2 | G3: -3
A4: PRE_CONC | B4: Preparedness | C4: 0.35 | D4: Infrastructure+Operations | E4: 0.25 | F4: -4 | G4: -2
A5: GOV_CONC | B5: Governance | C5: 0.35 | D5: Infrastructure+Operations+Preparedness | E5: 0.3 | F5: -4 | G5: -1
A6: BEH_CONC | B6: Behavioural | C6: 0.35 | D6: Infrastructure+Operations+Preparedness | E6: 0.3 | F6: -4 | G6: -3
A7: RES_CONC | B7: Restrictive | C7: 0.35 | D7: Operations+Preparedness+Governance | E7: 0.3 | F7: -1 | G7: -5

Sheet Events
A1: Event ID | B1: Scenario | C1: Deck | D1: Event title | E1: Risk | F1: Resilience | G1: Continuity | H1: Acceptability | I1: Budget
A2: EVT-V2-PC-01 | B2: PC | C2: intermediate | D2: Early severe heatwave | E2: 8 | F2: -3 | G2: -5 | H2: -1 | I2: 0
A3: EVT-V2-PC-02 | B3: PC | C3: intermediate | D3: Cooling-system stress | E3: 7 | F3: -3 | G3: -7 | H3: -1 | I3: -3
A4: EVT-V2-PC-03 | B4: PC | C4: intermediate | D4: Procurement delay | E4: 3 | F4: -2 | G4: -5 | H4: -1 | I4: -6
A5: EVT-V2-PC-04 | B5: PC | C5: intermediate | D5: Public demand for visible action | E5: 2 | F5: -1 | G5: -2 | H5: -5 | I5: 0
A6: EVT-V2-PC-05 | B6: PC | C6: intermediate | D6: Resistance to repeated restrictions | E6: 1 | F6: -1 | G6: -2 | H6: -7 | I6: 0
A7: EVT-V2-PC-06 | B7: PC | C7: intermediate | D7: Emergency coordination opportunity | E7: -2 | F7: 3 | G7: 3 | H7: 2 | I7: -1
A8: EVT-V2-PC-07 | B8: PC | C8: intermediate | D8: Supplementary adaptation funding | E8: 0 | F8: 0 | G8: 0 | H8: 0 | I8: 0
A9: EVT-V2-PC-08 | B9: PC | C9: intermediate | D9: Interdepartmental mobilisation | E9: 0 | F9: 0 | G9: 0 | H9: 0 | I9: 0
A10: EVT-V2-PC-09 | B10: PC | C10: final | D10: Compound heat and service-continuity stress | E10: 12 | F10: -6 | G10: -9 | H10: -3 | I10: -2
A11: EVT-V2-PC-10 | B11: PC | C11: final | D11: Grid-pressure emergency | E11: 10 | F11: -5 | G11: -11 | H11: -2 | I11: -5
A12: EVT-V2-PC-11 | B12: PC | C12: final | D12: Supply-chain disruption | E12: 7 | F12: -4 | G12: -7 | H12: -2 | I12: -8
A13: EVT-V2-PC-12 | B13: PC | C13: final | D13: Heat-health escalation | E13: 14 | F13: -8 | G13: -6 | H13: -5 | I13: -3
... A49: EVT-V2-SR-12 | B49: SR | C49: final | D49: Compound hidden-risk event | E49: 11 | F49: -8 | G49: -8 | H49: -5 | I49: -3

Sheet Parameters
A1: M.parameters key | B1: Value
A2: coordinationLoad.contractVersion | B2: coordination-load-v2
A3: coordinationLoad.actionWeights.start | B3: 0.4
A4: coordinationLoad.actionWeights.upgrade | B4: 0.2
A5: coordinationLoad.actionWeights.repair | B5: 0.1
A6: coordinationLoad.heterogeneityByCategoryCount.0 | B6: 0
A7: coordinationLoad.heterogeneityByCategoryCount.1 | B7: 0
A8: coordinationLoad.heterogeneityByCategoryCount.2 | B8: 0
A9: coordinationLoad.heterogeneityByCategoryCount.3 | B9: 1
A10: coordinationLoad.heterogeneityByCategoryCount.4 | B10: 3
A11: coordinationLoad.heterogeneityByCategoryCount.5 | B11: 6
A12: coordinationLoad.heterogeneityByCategoryCount.6 | B12: 10
A13: coordinationLoad.positiveSpanningLinkBonus | B13: 0.5
A14: coordinationLoad.capacity | B14: 4
... A28: positiveInteractionResilienceCap | B28: 10
A29: residualRisk.form | B29: asymptotic-with-hard-floor
A30: residualRisk.k.PC | B30: 22
A31: residualRisk.k.FF | B31: 27
A32: residualRisk.k.CZ | B32: 8
A33: residualRisk.k.SR | B33: 11
A34: acceptability.weightedMeanShare | B34: 0.7
A35: acceptability.minimumShare | B35: 0.3
A36: activeScoreRebalance.contractVersion | B36: active-score-rebalance-v1
A37: activeScoreRebalance.dynamicCoordination.enabled | B37: TRUE
A38: activeScoreRebalance.dynamicCoordination.eligibleCategories.0 | B38: Governance
A39: activeScoreRebalance.dynamicCoordination.eligibleCategories.1 | B39: Operations
A40: activeScoreRebalance.dynamicCoordination.eligibleTags.0 | B40: coordination
A41: activeScoreRebalance.dynamicCoordination.eligibleTags.1 | B41: planning
A42: activeScoreRebalance.dynamicCoordination.eligibleTags.2 | B42: monitoring
A43: activeScoreRebalance.dynamicCoordination.eligibleTags.3 | B43: continuity
A44: activeScoreRebalance.dynamicCoordination.minimumMaturity | B44: 0.5
A45: activeScoreRebalance.dynamicCoordination.contributionPerMatureLevel | B45: 0.5
A46: activeScoreRebalance.dynamicCoordination.perInterventionCap | B46: 0.5
A47: activeScoreRebalance.dynamicCoordination.maximumBonus | B47: 1
A48: activeScoreRebalance.coherence.mode | B48: graded-compatible-capacity
A49: activeScoreRebalance.coherence.structuralWeight | B49: 0.7
A50: activeScoreRebalance.coherence.responseWeight | B50: 0.3
A51: activeScoreRebalance.coherence.firstTurnStructuralOnly | B51: TRUE
A52: activeScoreRebalance.coherence.fullResponseCapacity | B52: 0.5
A53: activeScoreRebalance.coherence.missedResponseCapacityThreshold | B53: 0.05
...
